<?xml version="1.0" encoding="utf-8"?>
<!-- This URDF was automatically created by SolidWorks to URDF Exporter! Originally created by Stephen Brawner (brawner@gmail.com) 
     Commit Version: 1.6.0-4-g7f85cfe  Build Version: 1.6.7995.38578
     For more information, please see http://wiki.ros.org/sw_urdf_exporter -->
<robot
  name="arm_v2_urdf">
  <link
    name="base_link">
    <inertial>
      <origin
        xyz="4.4365E-05 -2.8885E-05 0.015822"
        rpy="0 0 0" />
      <mass
        value="0.42807" />
      <inertia
        ixx="0.00057547"
        ixy="-3.6263E-07"
        ixz="-3.0636E-08"
        iyy="0.00063496"
        iyz="2.5285E-08"
        izz="0.0011899" />
    </inertial>
    <visual>
      <origin
        xyz="0 0 0"
        rpy="0 0 0" />
      <geometry>
        <mesh
          filename="package://arm_v2_urdf/meshes/base_link.STL" />
      </geometry>
      <material
        name="">
        <color
          rgba="0.75294 0.75294 0.75294 1" />
      </material>
    </visual>
    <collision>
      <origin
        xyz="0 0 0"
        rpy="0 0 0" />
      <geometry>
        <mesh
          filename="package://arm_v2_urdf/meshes/base_link.STL" />
      </geometry>
    </collision>
  </link>
  <link
    name="link1">
    <inertial>
      <origin
        xyz="4.0905E-05 -0.0084473 0.023088"
        rpy="0 0 0" />
      <mass
        value="0.3024" />
      <inertia
        ixx="0.00031936"
        ixy="3.6285E-07"
        ixz="-2.5304E-08"
        iyy="0.00021488"
        iyz="3.6187E-05"
        izz="0.00046044" />
    </inertial>
    <visual>
      <origin
        xyz="0 0 0"
        rpy="0 0 0" />
      <geometry>
        <mesh
          filename="package://arm_v2_urdf/meshes/link1.STL" />
      </geometry>
      <material
        name="">
        <color
          rgba="0.79216 0.81961 0.93333 1" />
      </material>
    </visual>
    <collision>
      <origin
        xyz="0 0 0"
        rpy="0 0 0" />
      <geometry>
        <mesh
          filename="package://arm_v2_urdf/meshes/link1.STL" />
      </geometry>
    </collision>
  </link>
  <joint
    name="joint1"
    type="continuous">
    <origin
      xyz="-0.0045366 -0.030621 0.1135"
      rpy="1.5708 0 2.9945" />
    <parent
      link="base_link" />
    <child
      link="link1" />
    <axis
      xyz="0 1 0" />
  </joint>
  <link
    name="link2">
    <inertial>
      <origin
        xyz="-0.00511373562031049 -0.033793084043802 0.0204873768512508"
        rpy="0 0 0" />
      <mass
        value="0.484000256888559" />
      <inertia
        ixx="0.00187358807656737"
        ixy="-8.58783468313879E-05"
        ixz="-4.39695550492937E-05"
        iyy="0.000323047947697138"
        iyz="-5.37153677487572E-05"
        izz="0.00214738608312367" />
    </inertial>
    <visual>
      <origin
        xyz="0 0 0"
        rpy="0 0 0" />
      <geometry>
        <mesh
          filename="package://arm_v2_urdf/meshes/link2.STL" />
      </geometry>
      <material
        name="">
        <color
          rgba="1 1 1 1" />
      </material>
    </visual>
    <collision>
      <origin
        xyz="0 0 0"
        rpy="0 0 0" />
      <geometry>
        <mesh
          filename="package://arm_v2_urdf/meshes/link2.STL" />
      </geometry>
    </collision>
  </link>
  <joint
    name="joint2"
    type="continuous">
    <origin
      xyz="-0.011915 0.19964 0.059"
      rpy="-3.1416 -0.14708 3.1416" />
    <parent
      link="link1" />
    <child
      link="link2" />
    <axis
      xyz="0.14655 0 -0.9892" />
  </joint>
  <link
    name="link3">
    <inertial>
      <origin
        xyz="-0.064421 -0.00011692 0.023017"
        rpy="0 0 0" />
      <mass
        value="0.43829" />
      <inertia
        ixx="0.00021024"
        ixy="7.1459E-06"
        ixz="7.5348E-05"
        iyy="0.00070366"
        iyz="-1.2904E-06"
        izz="0.0007491" />
    </inertial>
    <visual>
      <origin
        xyz="0 0 0"
        rpy="0 0 0" />
      <geometry>
        <mesh
          filename="package://arm_v2_urdf/meshes/link3.STL" />
      </geometry>
      <material
        name="">
        <color
          rgba="1 1 1 1" />
      </material>
    </visual>
    <collision>
      <origin
        xyz="0 0 0"
        rpy="0 0 0" />
      <geometry>
        <mesh
          filename="package://arm_v2_urdf/meshes/link3.STL" />
      </geometry>
    </collision>
  </link>
  <joint
    name="joint3"
    type="continuous">
    <origin
      xyz="-0.008027 0.011577 0.20959"
      rpy="-2.6713 -1.4237 3.1416" />
    <parent
      link="link2" />
    <child
      link="link3" />
    <axis
      xyz="1 0 0" />
  </joint>
  <link
    name="link4">
    <inertial>
      <origin
        xyz="0.024776 0.014467 0.017034"
        rpy="0 0 0" />
      <mass
        value="0.26455" />
      <inertia
        ixx="0.00024995"
        ixy="-0.00027068"
        ixz="1.1963E-05"
        iyy="0.00060801"
        iyz="5.9717E-06"
        izz="0.00084305" />
    </inertial>
    <visual>
      <origin
        xyz="0 0 0"
        rpy="0 0 0" />
      <geometry>
        <mesh
          filename="package://arm_v2_urdf/meshes/link4.STL" />
      </geometry>
      <material
        name="">
        <color
          rgba="1 1 1 1" />
      </material>
    </visual>
    <collision>
      <origin
        xyz="0 0 0"
        rpy="0 0 0" />
      <geometry>
        <mesh
          filename="package://arm_v2_urdf/meshes/link4.STL" />
      </geometry>
    </collision>
  </link>
  <joint
    name="joint4"
    type="continuous">
    <origin
      xyz="0.15844 -0.085433 0.050774"
      rpy="3.1416 0 3.1416" />
    <parent
      link="link3" />
    <child
      link="link4" />
    <axis
      xyz="0 0 1" />
  </joint>
  <link
    name="link5">
    <inertial>
      <origin
        xyz="-0.00013074 -1.9051E-05 -0.041743"
        rpy="0 0 0" />
      <mass
        value="0.069862" />
      <inertia
        ixx="8.9302E-05"
        ixy="4.1408E-06"
        ixz="1.5275E-09"
        iyy="8.581E-05"
        iyz="1.0137E-09"
        izz="1.5267E-05" />
    </inertial>
    <visual>
      <origin
        xyz="0 0 0"
        rpy="0 0 0" />
      <geometry>
        <mesh
          filename="package://arm_v2_urdf/meshes/link5.STL" />
      </geometry>
      <material
        name="">
        <color
          rgba="0.75294 0.75294 0.75294 1" />
      </material>
    </visual>
    <collision>
      <origin
        xyz="0 0 0"
        rpy="0 0 0" />
      <geometry>
        <mesh
          filename="package://arm_v2_urdf/meshes/link5.STL" />
      </geometry>
    </collision>
  </link>
  <joint
    name="joint5"
    type="continuous">
    <origin
      xyz="-0.078368 -0.063176 0.052274"
      rpy="1.5708 -0.98492 -0.87264" />
    <parent
      link="link4" />
    <child
      link="link5" />
    <axis
      xyz="0.83323 0.55293 0" />
  </joint>
  <link
    name="link6">
    <inertial>
      <origin
        xyz="0.00095478 -4.2399E-05 0.048577"
        rpy="0 0 0" />
      <mass
        value="0.062709" />
      <inertia
        ixx="3.8761E-05"
        ixy="-3.2505E-08"
        ixz="1.4034E-06"
        iyy="8.1632E-05"
        iyz="-6.3917E-07"
        izz="4.6983E-05" />
    </inertial>
    <visual>
      <origin
        xyz="0 0 0"
        rpy="0 0 0" />
      <geometry>
        <mesh
          filename="package://arm_v2_urdf/meshes/link6.STL" />
      </geometry>
      <material
        name="">
        <color
          rgba="1 1 1 1" />
      </material>
    </visual>
    <collision>
      <origin
        xyz="0 0 0"
        rpy="0 0 0" />
      <geometry>
        <mesh
          filename="package://arm_v2_urdf/meshes/link6.STL" />
      </geometry>
    </collision>
  </link>
  <joint
    name="joint6"
    type="continuous">
    <origin
      xyz="-0.0083167 -0.0047388 0.05485"
      rpy="0 0 -0.95023" />
    <parent
      link="link5" />
    <child
      link="link6" />
    <axis
      xyz="0 0 1" />
  </joint>
</robot>